[2022-11-10 09:11:56,882] {taskinstance.py:1032} INFO - Dependencies all met for <TaskInstance: yellow_taxi_data_V2.local_to_gcs_task backfill__2019-02-02T06:00:00+00:00 [queued]>
[2022-11-10 09:11:56,894] {taskinstance.py:1032} INFO - Dependencies all met for <TaskInstance: yellow_taxi_data_V2.local_to_gcs_task backfill__2019-02-02T06:00:00+00:00 [queued]>
[2022-11-10 09:11:56,895] {taskinstance.py:1238} INFO - 
--------------------------------------------------------------------------------
[2022-11-10 09:11:56,895] {taskinstance.py:1239} INFO - Starting attempt 2 of 2
[2022-11-10 09:11:56,895] {taskinstance.py:1240} INFO - 
--------------------------------------------------------------------------------
[2022-11-10 09:11:56,910] {taskinstance.py:1259} INFO - Executing <Task(PythonOperator): local_to_gcs_task> on 2019-02-02 06:00:00+00:00
[2022-11-10 09:11:56,919] {standard_task_runner.py:52} INFO - Started process 4648 to run task
[2022-11-10 09:11:56,929] {standard_task_runner.py:76} INFO - Running: ['***', 'tasks', 'run', 'yellow_taxi_data_V2', 'local_to_gcs_task', 'backfill__2019-02-02T06:00:00+00:00', '--job-id', '43', '--pool', 'default_pool', '--raw', '--subdir', 'DAGS_FOLDER/data_ingestion_gcs_dag.py', '--cfg-path', '/tmp/tmp6f42zgon', '--error-file', '/tmp/tmprfch9gyh']
[2022-11-10 09:11:56,931] {standard_task_runner.py:77} INFO - Job 43: Subtask local_to_gcs_task
[2022-11-10 09:11:57,040] {logging_mixin.py:109} INFO - Running <TaskInstance: yellow_taxi_data_V2.local_to_gcs_task backfill__2019-02-02T06:00:00+00:00 [running]> on host e2ff445f4993
[2022-11-10 09:11:57,110] {warnings.py:110} WARNING - /home/***/.local/lib/python3.7/site-packages/***/utils/context.py:152: AirflowContextDeprecationWarning: Accessing 'execution_date' from the template is deprecated and will be removed in a future version. Please use 'data_interval_start' or 'logical_date' instead.
  warnings.warn(_create_deprecation_warning(key, self._deprecation_replacements[key]))

[2022-11-10 09:11:57,146] {taskinstance.py:1426} INFO - Exporting the following env vars:
AIRFLOW_CTX_DAG_OWNER=***
AIRFLOW_CTX_DAG_ID=yellow_taxi_data_V2
AIRFLOW_CTX_TASK_ID=local_to_gcs_task
AIRFLOW_CTX_EXECUTION_DATE=2019-02-02T06:00:00+00:00
AIRFLOW_CTX_DAG_RUN_ID=backfill__2019-02-02T06:00:00+00:00
[2022-11-10 09:11:57,149] {taskinstance.py:1700} ERROR - Task failed with exception
Traceback (most recent call last):
  File "/home/airflow/.local/lib/python3.7/site-packages/airflow/models/taskinstance.py", line 1329, in _run_raw_task
    self._execute_task_with_callbacks(context)
  File "/home/airflow/.local/lib/python3.7/site-packages/airflow/models/taskinstance.py", line 1455, in _execute_task_with_callbacks
    result = self._execute_task(context, self.task)
  File "/home/airflow/.local/lib/python3.7/site-packages/airflow/models/taskinstance.py", line 1511, in _execute_task
    result = execute_callable(context=context)
  File "/home/airflow/.local/lib/python3.7/site-packages/airflow/operators/python.py", line 174, in execute
    return_value = self.execute_callable()
  File "/home/airflow/.local/lib/python3.7/site-packages/airflow/operators/python.py", line 185, in execute_callable
    return self.python_callable(*self.op_args, **self.op_kwargs)
  File "/opt/airflow/dags/data_ingestion_gcs_dag.py", line 61, in upload_to_gcs
    client = storage.Client() # creates a client for gcs storage
  File "/home/airflow/.local/lib/python3.7/site-packages/google/cloud/storage/client.py", line 128, in __init__
    _http=_http,
  File "/home/airflow/.local/lib/python3.7/site-packages/google/cloud/client.py", line 318, in __init__
    _ClientProjectMixin.__init__(self, project=project, credentials=credentials)
  File "/home/airflow/.local/lib/python3.7/site-packages/google/cloud/client.py", line 266, in __init__
    project = self._determine_default(project)
  File "/home/airflow/.local/lib/python3.7/site-packages/google/cloud/client.py", line 285, in _determine_default
    return _determine_default_project(project)
  File "/home/airflow/.local/lib/python3.7/site-packages/google/cloud/_helpers.py", line 186, in _determine_default_project
    _, project = google.auth.default()
  File "/home/airflow/.local/lib/python3.7/site-packages/google/auth/_default.py", line 459, in default
    credentials, project_id = checker()
  File "/home/airflow/.local/lib/python3.7/site-packages/google/auth/_default.py", line 222, in _get_explicit_environ_credentials
    os.environ[environment_vars.CREDENTIALS]
  File "/home/airflow/.local/lib/python3.7/site-packages/google/auth/_default.py", line 108, in load_credentials_from_file
    "File {} was not found.".format(filename)
google.auth.exceptions.DefaultCredentialsError: File /.google/credentials/google_credentials.json was not found.
[2022-11-10 09:11:57,180] {taskinstance.py:1277} INFO - Marking task as FAILED. dag_id=yellow_taxi_data_V2, task_id=local_to_gcs_task, execution_date=20190202T060000, start_date=20221110T091156, end_date=20221110T091157
[2022-11-10 09:11:57,202] {standard_task_runner.py:92} ERROR - Failed to execute job 43 for task local_to_gcs_task
Traceback (most recent call last):
  File "/home/airflow/.local/lib/python3.7/site-packages/airflow/task/task_runner/standard_task_runner.py", line 85, in _start_by_fork
    args.func(args, dag=self.dag)
  File "/home/airflow/.local/lib/python3.7/site-packages/airflow/cli/cli_parser.py", line 48, in command
    return func(*args, **kwargs)
  File "/home/airflow/.local/lib/python3.7/site-packages/airflow/utils/cli.py", line 92, in wrapper
    return f(*args, **kwargs)
  File "/home/airflow/.local/lib/python3.7/site-packages/airflow/cli/commands/task_command.py", line 298, in task_run
    _run_task_by_selected_method(args, dag, ti)
  File "/home/airflow/.local/lib/python3.7/site-packages/airflow/cli/commands/task_command.py", line 107, in _run_task_by_selected_method
    _run_raw_task(args, ti)
  File "/home/airflow/.local/lib/python3.7/site-packages/airflow/cli/commands/task_command.py", line 184, in _run_raw_task
    error_file=args.error_file,
  File "/home/airflow/.local/lib/python3.7/site-packages/airflow/utils/session.py", line 70, in wrapper
    return func(*args, session=session, **kwargs)
  File "/home/airflow/.local/lib/python3.7/site-packages/airflow/models/taskinstance.py", line 1329, in _run_raw_task
    self._execute_task_with_callbacks(context)
  File "/home/airflow/.local/lib/python3.7/site-packages/airflow/models/taskinstance.py", line 1455, in _execute_task_with_callbacks
    result = self._execute_task(context, self.task)
  File "/home/airflow/.local/lib/python3.7/site-packages/airflow/models/taskinstance.py", line 1511, in _execute_task
    result = execute_callable(context=context)
  File "/home/airflow/.local/lib/python3.7/site-packages/airflow/operators/python.py", line 174, in execute
    return_value = self.execute_callable()
  File "/home/airflow/.local/lib/python3.7/site-packages/airflow/operators/python.py", line 185, in execute_callable
    return self.python_callable(*self.op_args, **self.op_kwargs)
  File "/opt/airflow/dags/data_ingestion_gcs_dag.py", line 61, in upload_to_gcs
    client = storage.Client() # creates a client for gcs storage
  File "/home/airflow/.local/lib/python3.7/site-packages/google/cloud/storage/client.py", line 128, in __init__
    _http=_http,
  File "/home/airflow/.local/lib/python3.7/site-packages/google/cloud/client.py", line 318, in __init__
    _ClientProjectMixin.__init__(self, project=project, credentials=credentials)
  File "/home/airflow/.local/lib/python3.7/site-packages/google/cloud/client.py", line 266, in __init__
    project = self._determine_default(project)
  File "/home/airflow/.local/lib/python3.7/site-packages/google/cloud/client.py", line 285, in _determine_default
    return _determine_default_project(project)
  File "/home/airflow/.local/lib/python3.7/site-packages/google/cloud/_helpers.py", line 186, in _determine_default_project
    _, project = google.auth.default()
  File "/home/airflow/.local/lib/python3.7/site-packages/google/auth/_default.py", line 459, in default
    credentials, project_id = checker()
  File "/home/airflow/.local/lib/python3.7/site-packages/google/auth/_default.py", line 222, in _get_explicit_environ_credentials
    os.environ[environment_vars.CREDENTIALS]
  File "/home/airflow/.local/lib/python3.7/site-packages/google/auth/_default.py", line 108, in load_credentials_from_file
    "File {} was not found.".format(filename)
google.auth.exceptions.DefaultCredentialsError: File /.google/credentials/google_credentials.json was not found.
[2022-11-10 09:11:57,230] {local_task_job.py:154} INFO - Task exited with return code 1
[2022-11-10 09:11:57,277] {local_task_job.py:264} INFO - 0 downstream tasks scheduled from follow-on schedule check
[2022-11-10 09:11:57,305] {dagrun.py:566} ERROR - Deadlock; marking run <DagRun yellow_taxi_data_V2 @ 2019-02-02 06:00:00+00:00: backfill__2019-02-02T06:00:00+00:00, externally triggered: False> failed
[2022-11-10 09:11:57,305] {dagrun.py:605} INFO - DagRun Finished: dag_id=yellow_taxi_data_V2, execution_date=2019-02-02 06:00:00+00:00, run_id=backfill__2019-02-02T06:00:00+00:00, run_start_date=2022-11-10 09:06:29.976451+00:00, run_end_date=2022-11-10 09:11:57.305907+00:00, run_duration=327.329456, state=failed, external_trigger=False, run_type=backfill, data_interval_start=2019-02-02 06:00:00+00:00, data_interval_end=2019-03-02 06:00:00+00:00, dag_hash=None
[2022-11-10 10:15:11,148] {taskinstance.py:1032} INFO - Dependencies all met for <TaskInstance: yellow_taxi_data_V2.local_to_gcs_task scheduled__2019-02-02T06:00:00+00:00 [queued]>
[2022-11-10 10:15:11,162] {taskinstance.py:1032} INFO - Dependencies all met for <TaskInstance: yellow_taxi_data_V2.local_to_gcs_task scheduled__2019-02-02T06:00:00+00:00 [queued]>
[2022-11-10 10:15:11,162] {taskinstance.py:1238} INFO - 
--------------------------------------------------------------------------------
[2022-11-10 10:15:11,162] {taskinstance.py:1239} INFO - Starting attempt 2 of 2
[2022-11-10 10:15:11,162] {taskinstance.py:1240} INFO - 
--------------------------------------------------------------------------------
[2022-11-10 10:15:11,179] {taskinstance.py:1259} INFO - Executing <Task(PythonOperator): local_to_gcs_task> on 2019-02-02 06:00:00+00:00
[2022-11-10 10:15:11,188] {standard_task_runner.py:52} INFO - Started process 7284 to run task
[2022-11-10 10:15:11,195] {standard_task_runner.py:76} INFO - Running: ['***', 'tasks', 'run', 'yellow_taxi_data_V2', 'local_to_gcs_task', 'scheduled__2019-02-02T06:00:00+00:00', '--job-id', '69', '--pool', 'default_pool', '--raw', '--subdir', 'DAGS_FOLDER/data_ingestion_gcs_dag.py', '--cfg-path', '/tmp/tmprsz_fsyx', '--error-file', '/tmp/tmpf40vvanv']
[2022-11-10 10:15:11,197] {standard_task_runner.py:77} INFO - Job 69: Subtask local_to_gcs_task
[2022-11-10 10:15:11,297] {logging_mixin.py:109} INFO - Running <TaskInstance: yellow_taxi_data_V2.local_to_gcs_task scheduled__2019-02-02T06:00:00+00:00 [running]> on host e2ff445f4993
[2022-11-10 10:15:11,370] {warnings.py:110} WARNING - /home/***/.local/lib/python3.7/site-packages/***/utils/context.py:152: AirflowContextDeprecationWarning: Accessing 'execution_date' from the template is deprecated and will be removed in a future version. Please use 'data_interval_start' or 'logical_date' instead.
  warnings.warn(_create_deprecation_warning(key, self._deprecation_replacements[key]))

[2022-11-10 10:15:11,395] {taskinstance.py:1426} INFO - Exporting the following env vars:
AIRFLOW_CTX_DAG_OWNER=***
AIRFLOW_CTX_DAG_ID=yellow_taxi_data_V2
AIRFLOW_CTX_TASK_ID=local_to_gcs_task
AIRFLOW_CTX_EXECUTION_DATE=2019-02-02T06:00:00+00:00
AIRFLOW_CTX_DAG_RUN_ID=scheduled__2019-02-02T06:00:00+00:00
[2022-11-10 10:15:11,396] {taskinstance.py:1700} ERROR - Task failed with exception
Traceback (most recent call last):
  File "/home/airflow/.local/lib/python3.7/site-packages/airflow/models/taskinstance.py", line 1329, in _run_raw_task
    self._execute_task_with_callbacks(context)
  File "/home/airflow/.local/lib/python3.7/site-packages/airflow/models/taskinstance.py", line 1455, in _execute_task_with_callbacks
    result = self._execute_task(context, self.task)
  File "/home/airflow/.local/lib/python3.7/site-packages/airflow/models/taskinstance.py", line 1511, in _execute_task
    result = execute_callable(context=context)
  File "/home/airflow/.local/lib/python3.7/site-packages/airflow/operators/python.py", line 174, in execute
    return_value = self.execute_callable()
  File "/home/airflow/.local/lib/python3.7/site-packages/airflow/operators/python.py", line 185, in execute_callable
    return self.python_callable(*self.op_args, **self.op_kwargs)
  File "/opt/airflow/dags/data_ingestion_gcs_dag.py", line 61, in upload_to_gcs
    client = storage.Client() # creates a client for gcs storage
  File "/home/airflow/.local/lib/python3.7/site-packages/google/cloud/storage/client.py", line 128, in __init__
    _http=_http,
  File "/home/airflow/.local/lib/python3.7/site-packages/google/cloud/client.py", line 318, in __init__
    _ClientProjectMixin.__init__(self, project=project, credentials=credentials)
  File "/home/airflow/.local/lib/python3.7/site-packages/google/cloud/client.py", line 266, in __init__
    project = self._determine_default(project)
  File "/home/airflow/.local/lib/python3.7/site-packages/google/cloud/client.py", line 285, in _determine_default
    return _determine_default_project(project)
  File "/home/airflow/.local/lib/python3.7/site-packages/google/cloud/_helpers.py", line 186, in _determine_default_project
    _, project = google.auth.default()
  File "/home/airflow/.local/lib/python3.7/site-packages/google/auth/_default.py", line 459, in default
    credentials, project_id = checker()
  File "/home/airflow/.local/lib/python3.7/site-packages/google/auth/_default.py", line 222, in _get_explicit_environ_credentials
    os.environ[environment_vars.CREDENTIALS]
  File "/home/airflow/.local/lib/python3.7/site-packages/google/auth/_default.py", line 108, in load_credentials_from_file
    "File {} was not found.".format(filename)
google.auth.exceptions.DefaultCredentialsError: File /.google/credentials/google_credentials.json was not found.
[2022-11-10 10:15:11,416] {taskinstance.py:1277} INFO - Marking task as FAILED. dag_id=yellow_taxi_data_V2, task_id=local_to_gcs_task, execution_date=20190202T060000, start_date=20221110T101511, end_date=20221110T101511
[2022-11-10 10:15:11,431] {standard_task_runner.py:92} ERROR - Failed to execute job 69 for task local_to_gcs_task
Traceback (most recent call last):
  File "/home/airflow/.local/lib/python3.7/site-packages/airflow/task/task_runner/standard_task_runner.py", line 85, in _start_by_fork
    args.func(args, dag=self.dag)
  File "/home/airflow/.local/lib/python3.7/site-packages/airflow/cli/cli_parser.py", line 48, in command
    return func(*args, **kwargs)
  File "/home/airflow/.local/lib/python3.7/site-packages/airflow/utils/cli.py", line 92, in wrapper
    return f(*args, **kwargs)
  File "/home/airflow/.local/lib/python3.7/site-packages/airflow/cli/commands/task_command.py", line 298, in task_run
    _run_task_by_selected_method(args, dag, ti)
  File "/home/airflow/.local/lib/python3.7/site-packages/airflow/cli/commands/task_command.py", line 107, in _run_task_by_selected_method
    _run_raw_task(args, ti)
  File "/home/airflow/.local/lib/python3.7/site-packages/airflow/cli/commands/task_command.py", line 184, in _run_raw_task
    error_file=args.error_file,
  File "/home/airflow/.local/lib/python3.7/site-packages/airflow/utils/session.py", line 70, in wrapper
    return func(*args, session=session, **kwargs)
  File "/home/airflow/.local/lib/python3.7/site-packages/airflow/models/taskinstance.py", line 1329, in _run_raw_task
    self._execute_task_with_callbacks(context)
  File "/home/airflow/.local/lib/python3.7/site-packages/airflow/models/taskinstance.py", line 1455, in _execute_task_with_callbacks
    result = self._execute_task(context, self.task)
  File "/home/airflow/.local/lib/python3.7/site-packages/airflow/models/taskinstance.py", line 1511, in _execute_task
    result = execute_callable(context=context)
  File "/home/airflow/.local/lib/python3.7/site-packages/airflow/operators/python.py", line 174, in execute
    return_value = self.execute_callable()
  File "/home/airflow/.local/lib/python3.7/site-packages/airflow/operators/python.py", line 185, in execute_callable
    return self.python_callable(*self.op_args, **self.op_kwargs)
  File "/opt/airflow/dags/data_ingestion_gcs_dag.py", line 61, in upload_to_gcs
    client = storage.Client() # creates a client for gcs storage
  File "/home/airflow/.local/lib/python3.7/site-packages/google/cloud/storage/client.py", line 128, in __init__
    _http=_http,
  File "/home/airflow/.local/lib/python3.7/site-packages/google/cloud/client.py", line 318, in __init__
    _ClientProjectMixin.__init__(self, project=project, credentials=credentials)
  File "/home/airflow/.local/lib/python3.7/site-packages/google/cloud/client.py", line 266, in __init__
    project = self._determine_default(project)
  File "/home/airflow/.local/lib/python3.7/site-packages/google/cloud/client.py", line 285, in _determine_default
    return _determine_default_project(project)
  File "/home/airflow/.local/lib/python3.7/site-packages/google/cloud/_helpers.py", line 186, in _determine_default_project
    _, project = google.auth.default()
  File "/home/airflow/.local/lib/python3.7/site-packages/google/auth/_default.py", line 459, in default
    credentials, project_id = checker()
  File "/home/airflow/.local/lib/python3.7/site-packages/google/auth/_default.py", line 222, in _get_explicit_environ_credentials
    os.environ[environment_vars.CREDENTIALS]
  File "/home/airflow/.local/lib/python3.7/site-packages/google/auth/_default.py", line 108, in load_credentials_from_file
    "File {} was not found.".format(filename)
google.auth.exceptions.DefaultCredentialsError: File /.google/credentials/google_credentials.json was not found.
[2022-11-10 10:15:11,448] {local_task_job.py:154} INFO - Task exited with return code 1
[2022-11-10 10:15:11,495] {local_task_job.py:264} INFO - 0 downstream tasks scheduled from follow-on schedule check
[2022-11-10 11:36:06,934] {taskinstance.py:1032} INFO - Dependencies all met for <TaskInstance: yellow_taxi_data_V2.local_to_gcs_task scheduled__2019-02-02T06:00:00+00:00 [queued]>
[2022-11-10 11:36:06,953] {taskinstance.py:1032} INFO - Dependencies all met for <TaskInstance: yellow_taxi_data_V2.local_to_gcs_task scheduled__2019-02-02T06:00:00+00:00 [queued]>
[2022-11-10 11:36:06,957] {taskinstance.py:1238} INFO - 
--------------------------------------------------------------------------------
[2022-11-10 11:36:06,957] {taskinstance.py:1239} INFO - Starting attempt 2 of 2
[2022-11-10 11:36:06,958] {taskinstance.py:1240} INFO - 
--------------------------------------------------------------------------------
[2022-11-10 11:36:06,987] {taskinstance.py:1259} INFO - Executing <Task(PythonOperator): local_to_gcs_task> on 2019-02-02 06:00:00+00:00
[2022-11-10 11:36:06,995] {standard_task_runner.py:52} INFO - Started process 10604 to run task
[2022-11-10 11:36:07,012] {standard_task_runner.py:76} INFO - Running: ['***', 'tasks', 'run', 'yellow_taxi_data_V2', 'local_to_gcs_task', 'scheduled__2019-02-02T06:00:00+00:00', '--job-id', '86', '--pool', 'default_pool', '--raw', '--subdir', 'DAGS_FOLDER/data_ingestion_gcs_dag.py', '--cfg-path', '/tmp/tmptxnaqyk4', '--error-file', '/tmp/tmp8w_u041j']
[2022-11-10 11:36:07,014] {standard_task_runner.py:77} INFO - Job 86: Subtask local_to_gcs_task
[2022-11-10 11:36:07,129] {logging_mixin.py:109} INFO - Running <TaskInstance: yellow_taxi_data_V2.local_to_gcs_task scheduled__2019-02-02T06:00:00+00:00 [running]> on host e2ff445f4993
[2022-11-10 11:36:07,200] {warnings.py:110} WARNING - /home/***/.local/lib/python3.7/site-packages/***/utils/context.py:152: AirflowContextDeprecationWarning: Accessing 'execution_date' from the template is deprecated and will be removed in a future version. Please use 'data_interval_start' or 'logical_date' instead.
  warnings.warn(_create_deprecation_warning(key, self._deprecation_replacements[key]))

[2022-11-10 11:36:07,233] {taskinstance.py:1426} INFO - Exporting the following env vars:
AIRFLOW_CTX_DAG_OWNER=***
AIRFLOW_CTX_DAG_ID=yellow_taxi_data_V2
AIRFLOW_CTX_TASK_ID=local_to_gcs_task
AIRFLOW_CTX_EXECUTION_DATE=2019-02-02T06:00:00+00:00
AIRFLOW_CTX_DAG_RUN_ID=scheduled__2019-02-02T06:00:00+00:00
[2022-11-10 11:36:07,235] {taskinstance.py:1700} ERROR - Task failed with exception
Traceback (most recent call last):
  File "/home/airflow/.local/lib/python3.7/site-packages/airflow/models/taskinstance.py", line 1329, in _run_raw_task
    self._execute_task_with_callbacks(context)
  File "/home/airflow/.local/lib/python3.7/site-packages/airflow/models/taskinstance.py", line 1455, in _execute_task_with_callbacks
    result = self._execute_task(context, self.task)
  File "/home/airflow/.local/lib/python3.7/site-packages/airflow/models/taskinstance.py", line 1511, in _execute_task
    result = execute_callable(context=context)
  File "/home/airflow/.local/lib/python3.7/site-packages/airflow/operators/python.py", line 174, in execute
    return_value = self.execute_callable()
  File "/home/airflow/.local/lib/python3.7/site-packages/airflow/operators/python.py", line 185, in execute_callable
    return self.python_callable(*self.op_args, **self.op_kwargs)
  File "/opt/airflow/dags/data_ingestion_gcs_dag.py", line 61, in upload_to_gcs
    client = storage.Client() # creates a client for gcs storage
  File "/home/airflow/.local/lib/python3.7/site-packages/google/cloud/storage/client.py", line 128, in __init__
    _http=_http,
  File "/home/airflow/.local/lib/python3.7/site-packages/google/cloud/client.py", line 318, in __init__
    _ClientProjectMixin.__init__(self, project=project, credentials=credentials)
  File "/home/airflow/.local/lib/python3.7/site-packages/google/cloud/client.py", line 266, in __init__
    project = self._determine_default(project)
  File "/home/airflow/.local/lib/python3.7/site-packages/google/cloud/client.py", line 285, in _determine_default
    return _determine_default_project(project)
  File "/home/airflow/.local/lib/python3.7/site-packages/google/cloud/_helpers.py", line 186, in _determine_default_project
    _, project = google.auth.default()
  File "/home/airflow/.local/lib/python3.7/site-packages/google/auth/_default.py", line 459, in default
    credentials, project_id = checker()
  File "/home/airflow/.local/lib/python3.7/site-packages/google/auth/_default.py", line 222, in _get_explicit_environ_credentials
    os.environ[environment_vars.CREDENTIALS]
  File "/home/airflow/.local/lib/python3.7/site-packages/google/auth/_default.py", line 108, in load_credentials_from_file
    "File {} was not found.".format(filename)
google.auth.exceptions.DefaultCredentialsError: File /.google/credentials/google_credentials.json was not found.
[2022-11-10 11:36:07,262] {taskinstance.py:1277} INFO - Marking task as FAILED. dag_id=yellow_taxi_data_V2, task_id=local_to_gcs_task, execution_date=20190202T060000, start_date=20221110T113606, end_date=20221110T113607
[2022-11-10 11:36:07,285] {standard_task_runner.py:92} ERROR - Failed to execute job 86 for task local_to_gcs_task
Traceback (most recent call last):
  File "/home/airflow/.local/lib/python3.7/site-packages/airflow/task/task_runner/standard_task_runner.py", line 85, in _start_by_fork
    args.func(args, dag=self.dag)
  File "/home/airflow/.local/lib/python3.7/site-packages/airflow/cli/cli_parser.py", line 48, in command
    return func(*args, **kwargs)
  File "/home/airflow/.local/lib/python3.7/site-packages/airflow/utils/cli.py", line 92, in wrapper
    return f(*args, **kwargs)
  File "/home/airflow/.local/lib/python3.7/site-packages/airflow/cli/commands/task_command.py", line 298, in task_run
    _run_task_by_selected_method(args, dag, ti)
  File "/home/airflow/.local/lib/python3.7/site-packages/airflow/cli/commands/task_command.py", line 107, in _run_task_by_selected_method
    _run_raw_task(args, ti)
  File "/home/airflow/.local/lib/python3.7/site-packages/airflow/cli/commands/task_command.py", line 184, in _run_raw_task
    error_file=args.error_file,
  File "/home/airflow/.local/lib/python3.7/site-packages/airflow/utils/session.py", line 70, in wrapper
    return func(*args, session=session, **kwargs)
  File "/home/airflow/.local/lib/python3.7/site-packages/airflow/models/taskinstance.py", line 1329, in _run_raw_task
    self._execute_task_with_callbacks(context)
  File "/home/airflow/.local/lib/python3.7/site-packages/airflow/models/taskinstance.py", line 1455, in _execute_task_with_callbacks
    result = self._execute_task(context, self.task)
  File "/home/airflow/.local/lib/python3.7/site-packages/airflow/models/taskinstance.py", line 1511, in _execute_task
    result = execute_callable(context=context)
  File "/home/airflow/.local/lib/python3.7/site-packages/airflow/operators/python.py", line 174, in execute
    return_value = self.execute_callable()
  File "/home/airflow/.local/lib/python3.7/site-packages/airflow/operators/python.py", line 185, in execute_callable
    return self.python_callable(*self.op_args, **self.op_kwargs)
  File "/opt/airflow/dags/data_ingestion_gcs_dag.py", line 61, in upload_to_gcs
    client = storage.Client() # creates a client for gcs storage
  File "/home/airflow/.local/lib/python3.7/site-packages/google/cloud/storage/client.py", line 128, in __init__
    _http=_http,
  File "/home/airflow/.local/lib/python3.7/site-packages/google/cloud/client.py", line 318, in __init__
    _ClientProjectMixin.__init__(self, project=project, credentials=credentials)
  File "/home/airflow/.local/lib/python3.7/site-packages/google/cloud/client.py", line 266, in __init__
    project = self._determine_default(project)
  File "/home/airflow/.local/lib/python3.7/site-packages/google/cloud/client.py", line 285, in _determine_default
    return _determine_default_project(project)
  File "/home/airflow/.local/lib/python3.7/site-packages/google/cloud/_helpers.py", line 186, in _determine_default_project
    _, project = google.auth.default()
  File "/home/airflow/.local/lib/python3.7/site-packages/google/auth/_default.py", line 459, in default
    credentials, project_id = checker()
  File "/home/airflow/.local/lib/python3.7/site-packages/google/auth/_default.py", line 222, in _get_explicit_environ_credentials
    os.environ[environment_vars.CREDENTIALS]
  File "/home/airflow/.local/lib/python3.7/site-packages/google/auth/_default.py", line 108, in load_credentials_from_file
    "File {} was not found.".format(filename)
google.auth.exceptions.DefaultCredentialsError: File /.google/credentials/google_credentials.json was not found.
[2022-11-10 11:36:07,307] {local_task_job.py:154} INFO - Task exited with return code 1
[2022-11-10 11:36:07,368] {local_task_job.py:264} INFO - 0 downstream tasks scheduled from follow-on schedule check
[2022-11-10 12:35:04,583] {taskinstance.py:1032} INFO - Dependencies all met for <TaskInstance: yellow_taxi_data_V2.local_to_gcs_task scheduled__2019-02-02T06:00:00+00:00 [queued]>
[2022-11-10 12:35:04,605] {taskinstance.py:1032} INFO - Dependencies all met for <TaskInstance: yellow_taxi_data_V2.local_to_gcs_task scheduled__2019-02-02T06:00:00+00:00 [queued]>
[2022-11-10 12:35:04,607] {taskinstance.py:1238} INFO - 
--------------------------------------------------------------------------------
[2022-11-10 12:35:04,607] {taskinstance.py:1239} INFO - Starting attempt 2 of 2
[2022-11-10 12:35:04,607] {taskinstance.py:1240} INFO - 
--------------------------------------------------------------------------------
[2022-11-10 12:35:04,632] {taskinstance.py:1259} INFO - Executing <Task(PythonOperator): local_to_gcs_task> on 2019-02-02 06:00:00+00:00
[2022-11-10 12:35:04,642] {standard_task_runner.py:52} INFO - Started process 13040 to run task
[2022-11-10 12:35:04,660] {standard_task_runner.py:76} INFO - Running: ['***', 'tasks', 'run', 'yellow_taxi_data_V2', 'local_to_gcs_task', 'scheduled__2019-02-02T06:00:00+00:00', '--job-id', '100', '--pool', 'default_pool', '--raw', '--subdir', 'DAGS_FOLDER/data_ingestion_gcs_dag.py', '--cfg-path', '/tmp/tmpgtpn0uw9', '--error-file', '/tmp/tmpmrc90_ki']
[2022-11-10 12:35:04,662] {standard_task_runner.py:77} INFO - Job 100: Subtask local_to_gcs_task
[2022-11-10 12:35:04,780] {logging_mixin.py:109} INFO - Running <TaskInstance: yellow_taxi_data_V2.local_to_gcs_task scheduled__2019-02-02T06:00:00+00:00 [running]> on host e2ff445f4993
[2022-11-10 12:35:04,856] {warnings.py:110} WARNING - /home/***/.local/lib/python3.7/site-packages/***/utils/context.py:152: AirflowContextDeprecationWarning: Accessing 'execution_date' from the template is deprecated and will be removed in a future version. Please use 'data_interval_start' or 'logical_date' instead.
  warnings.warn(_create_deprecation_warning(key, self._deprecation_replacements[key]))

[2022-11-10 12:35:04,882] {taskinstance.py:1426} INFO - Exporting the following env vars:
AIRFLOW_CTX_DAG_OWNER=***
AIRFLOW_CTX_DAG_ID=yellow_taxi_data_V2
AIRFLOW_CTX_TASK_ID=local_to_gcs_task
AIRFLOW_CTX_EXECUTION_DATE=2019-02-02T06:00:00+00:00
AIRFLOW_CTX_DAG_RUN_ID=scheduled__2019-02-02T06:00:00+00:00
[2022-11-10 12:35:04,884] {taskinstance.py:1700} ERROR - Task failed with exception
Traceback (most recent call last):
  File "/home/airflow/.local/lib/python3.7/site-packages/airflow/models/taskinstance.py", line 1329, in _run_raw_task
    self._execute_task_with_callbacks(context)
  File "/home/airflow/.local/lib/python3.7/site-packages/airflow/models/taskinstance.py", line 1455, in _execute_task_with_callbacks
    result = self._execute_task(context, self.task)
  File "/home/airflow/.local/lib/python3.7/site-packages/airflow/models/taskinstance.py", line 1511, in _execute_task
    result = execute_callable(context=context)
  File "/home/airflow/.local/lib/python3.7/site-packages/airflow/operators/python.py", line 174, in execute
    return_value = self.execute_callable()
  File "/home/airflow/.local/lib/python3.7/site-packages/airflow/operators/python.py", line 185, in execute_callable
    return self.python_callable(*self.op_args, **self.op_kwargs)
  File "/opt/airflow/dags/data_ingestion_gcs_dag.py", line 62, in upload_to_gcs
    client = storage.Client() # creates a client for gcs storage
  File "/home/airflow/.local/lib/python3.7/site-packages/google/cloud/storage/client.py", line 128, in __init__
    _http=_http,
  File "/home/airflow/.local/lib/python3.7/site-packages/google/cloud/client.py", line 318, in __init__
    _ClientProjectMixin.__init__(self, project=project, credentials=credentials)
  File "/home/airflow/.local/lib/python3.7/site-packages/google/cloud/client.py", line 266, in __init__
    project = self._determine_default(project)
  File "/home/airflow/.local/lib/python3.7/site-packages/google/cloud/client.py", line 285, in _determine_default
    return _determine_default_project(project)
  File "/home/airflow/.local/lib/python3.7/site-packages/google/cloud/_helpers.py", line 186, in _determine_default_project
    _, project = google.auth.default()
  File "/home/airflow/.local/lib/python3.7/site-packages/google/auth/_default.py", line 459, in default
    credentials, project_id = checker()
  File "/home/airflow/.local/lib/python3.7/site-packages/google/auth/_default.py", line 222, in _get_explicit_environ_credentials
    os.environ[environment_vars.CREDENTIALS]
  File "/home/airflow/.local/lib/python3.7/site-packages/google/auth/_default.py", line 108, in load_credentials_from_file
    "File {} was not found.".format(filename)
google.auth.exceptions.DefaultCredentialsError: File /.google/credentials/google_credentials.json was not found.
[2022-11-10 12:35:04,900] {taskinstance.py:1277} INFO - Marking task as FAILED. dag_id=yellow_taxi_data_V2, task_id=local_to_gcs_task, execution_date=20190202T060000, start_date=20221110T123504, end_date=20221110T123504
[2022-11-10 12:35:04,920] {standard_task_runner.py:92} ERROR - Failed to execute job 100 for task local_to_gcs_task
Traceback (most recent call last):
  File "/home/airflow/.local/lib/python3.7/site-packages/airflow/task/task_runner/standard_task_runner.py", line 85, in _start_by_fork
    args.func(args, dag=self.dag)
  File "/home/airflow/.local/lib/python3.7/site-packages/airflow/cli/cli_parser.py", line 48, in command
    return func(*args, **kwargs)
  File "/home/airflow/.local/lib/python3.7/site-packages/airflow/utils/cli.py", line 92, in wrapper
    return f(*args, **kwargs)
  File "/home/airflow/.local/lib/python3.7/site-packages/airflow/cli/commands/task_command.py", line 298, in task_run
    _run_task_by_selected_method(args, dag, ti)
  File "/home/airflow/.local/lib/python3.7/site-packages/airflow/cli/commands/task_command.py", line 107, in _run_task_by_selected_method
    _run_raw_task(args, ti)
  File "/home/airflow/.local/lib/python3.7/site-packages/airflow/cli/commands/task_command.py", line 184, in _run_raw_task
    error_file=args.error_file,
  File "/home/airflow/.local/lib/python3.7/site-packages/airflow/utils/session.py", line 70, in wrapper
    return func(*args, session=session, **kwargs)
  File "/home/airflow/.local/lib/python3.7/site-packages/airflow/models/taskinstance.py", line 1329, in _run_raw_task
    self._execute_task_with_callbacks(context)
  File "/home/airflow/.local/lib/python3.7/site-packages/airflow/models/taskinstance.py", line 1455, in _execute_task_with_callbacks
    result = self._execute_task(context, self.task)
  File "/home/airflow/.local/lib/python3.7/site-packages/airflow/models/taskinstance.py", line 1511, in _execute_task
    result = execute_callable(context=context)
  File "/home/airflow/.local/lib/python3.7/site-packages/airflow/operators/python.py", line 174, in execute
    return_value = self.execute_callable()
  File "/home/airflow/.local/lib/python3.7/site-packages/airflow/operators/python.py", line 185, in execute_callable
    return self.python_callable(*self.op_args, **self.op_kwargs)
  File "/opt/airflow/dags/data_ingestion_gcs_dag.py", line 62, in upload_to_gcs
    client = storage.Client() # creates a client for gcs storage
  File "/home/airflow/.local/lib/python3.7/site-packages/google/cloud/storage/client.py", line 128, in __init__
    _http=_http,
  File "/home/airflow/.local/lib/python3.7/site-packages/google/cloud/client.py", line 318, in __init__
    _ClientProjectMixin.__init__(self, project=project, credentials=credentials)
  File "/home/airflow/.local/lib/python3.7/site-packages/google/cloud/client.py", line 266, in __init__
    project = self._determine_default(project)
  File "/home/airflow/.local/lib/python3.7/site-packages/google/cloud/client.py", line 285, in _determine_default
    return _determine_default_project(project)
  File "/home/airflow/.local/lib/python3.7/site-packages/google/cloud/_helpers.py", line 186, in _determine_default_project
    _, project = google.auth.default()
  File "/home/airflow/.local/lib/python3.7/site-packages/google/auth/_default.py", line 459, in default
    credentials, project_id = checker()
  File "/home/airflow/.local/lib/python3.7/site-packages/google/auth/_default.py", line 222, in _get_explicit_environ_credentials
    os.environ[environment_vars.CREDENTIALS]
  File "/home/airflow/.local/lib/python3.7/site-packages/google/auth/_default.py", line 108, in load_credentials_from_file
    "File {} was not found.".format(filename)
google.auth.exceptions.DefaultCredentialsError: File /.google/credentials/google_credentials.json was not found.
[2022-11-10 12:35:04,953] {local_task_job.py:154} INFO - Task exited with return code 1
[2022-11-10 12:35:05,011] {local_task_job.py:264} INFO - 0 downstream tasks scheduled from follow-on schedule check
