[2022-11-14 16:41:00,929] {taskinstance.py:1032} INFO - Dependencies all met for <TaskInstance: fhv_taxi_data_v1.download_dataset_task scheduled__2022-09-02T08:00:00+00:00 [queued]>
[2022-11-14 16:41:00,949] {taskinstance.py:1032} INFO - Dependencies all met for <TaskInstance: fhv_taxi_data_v1.download_dataset_task scheduled__2022-09-02T08:00:00+00:00 [queued]>
[2022-11-14 16:41:00,949] {taskinstance.py:1238} INFO - 
--------------------------------------------------------------------------------
[2022-11-14 16:41:00,949] {taskinstance.py:1239} INFO - Starting attempt 1 of 2
[2022-11-14 16:41:00,949] {taskinstance.py:1240} INFO - 
--------------------------------------------------------------------------------
[2022-11-14 16:41:00,981] {taskinstance.py:1259} INFO - Executing <Task(BashOperator): download_dataset_task> on 2022-09-02 08:00:00+00:00
[2022-11-14 16:41:00,989] {standard_task_runner.py:52} INFO - Started process 4954 to run task
[2022-11-14 16:41:00,999] {standard_task_runner.py:76} INFO - Running: ['***', 'tasks', 'run', 'fhv_taxi_data_v1', 'download_dataset_task', 'scheduled__2022-09-02T08:00:00+00:00', '--job-id', '682', '--raw', '--subdir', 'DAGS_FOLDER/data_ingestion_gcs.py', '--cfg-path', '/tmp/tmpamp223uz', '--error-file', '/tmp/tmpzalypgkq']
[2022-11-14 16:41:01,000] {standard_task_runner.py:77} INFO - Job 682: Subtask download_dataset_task
[2022-11-14 16:41:01,084] {logging_mixin.py:109} INFO - Running <TaskInstance: fhv_taxi_data_v1.download_dataset_task scheduled__2022-09-02T08:00:00+00:00 [running]> on host e030bae48f83
[2022-11-14 16:41:01,140] {warnings.py:110} WARNING - /home/***/.local/lib/python3.7/site-packages/***/utils/context.py:152: AirflowContextDeprecationWarning: Accessing 'execution_date' from the template is deprecated and will be removed in a future version. Please use 'data_interval_start' or 'logical_date' instead.
  warnings.warn(_create_deprecation_warning(key, self._deprecation_replacements[key]))

[2022-11-14 16:41:01,171] {taskinstance.py:1426} INFO - Exporting the following env vars:
AIRFLOW_CTX_DAG_OWNER=***
AIRFLOW_CTX_DAG_ID=fhv_taxi_data_v1
AIRFLOW_CTX_TASK_ID=download_dataset_task
AIRFLOW_CTX_EXECUTION_DATE=2022-09-02T08:00:00+00:00
AIRFLOW_CTX_DAG_RUN_ID=scheduled__2022-09-02T08:00:00+00:00
[2022-11-14 16:41:01,173] {subprocess.py:62} INFO - Tmp dir root location: 
 /tmp
[2022-11-14 16:41:01,173] {subprocess.py:74} INFO - Running command: ['bash', '-c', 'curl -sSLf https://d37ci6vzurychx.cloudfront.net/trip-data/fhv_tripdata_2022-09.parquet > /opt/***/fhv_tripdata_2022-09.parquet']
[2022-11-14 16:41:01,192] {subprocess.py:85} INFO - Output:
[2022-11-14 16:41:01,550] {subprocess.py:89} INFO - curl: (22) The requested URL returned error: 403
[2022-11-14 16:41:01,553] {subprocess.py:93} INFO - Command exited with return code 22
[2022-11-14 16:41:01,575] {taskinstance.py:1700} ERROR - Task failed with exception
Traceback (most recent call last):
  File "/home/airflow/.local/lib/python3.7/site-packages/airflow/models/taskinstance.py", line 1329, in _run_raw_task
    self._execute_task_with_callbacks(context)
  File "/home/airflow/.local/lib/python3.7/site-packages/airflow/models/taskinstance.py", line 1455, in _execute_task_with_callbacks
    result = self._execute_task(context, self.task)
  File "/home/airflow/.local/lib/python3.7/site-packages/airflow/models/taskinstance.py", line 1511, in _execute_task
    result = execute_callable(context=context)
  File "/home/airflow/.local/lib/python3.7/site-packages/airflow/operators/bash.py", line 188, in execute
    f'Bash command failed. The command returned a non-zero exit code {result.exit_code}.'
airflow.exceptions.AirflowException: Bash command failed. The command returned a non-zero exit code 22.
[2022-11-14 16:41:01,585] {taskinstance.py:1277} INFO - Marking task as UP_FOR_RETRY. dag_id=fhv_taxi_data_v1, task_id=download_dataset_task, execution_date=20220902T080000, start_date=20221114T164100, end_date=20221114T164101
[2022-11-14 16:41:01,605] {standard_task_runner.py:92} ERROR - Failed to execute job 682 for task download_dataset_task
Traceback (most recent call last):
  File "/home/airflow/.local/lib/python3.7/site-packages/airflow/task/task_runner/standard_task_runner.py", line 85, in _start_by_fork
    args.func(args, dag=self.dag)
  File "/home/airflow/.local/lib/python3.7/site-packages/airflow/cli/cli_parser.py", line 48, in command
    return func(*args, **kwargs)
  File "/home/airflow/.local/lib/python3.7/site-packages/airflow/utils/cli.py", line 92, in wrapper
    return f(*args, **kwargs)
  File "/home/airflow/.local/lib/python3.7/site-packages/airflow/cli/commands/task_command.py", line 298, in task_run
    _run_task_by_selected_method(args, dag, ti)
  File "/home/airflow/.local/lib/python3.7/site-packages/airflow/cli/commands/task_command.py", line 107, in _run_task_by_selected_method
    _run_raw_task(args, ti)
  File "/home/airflow/.local/lib/python3.7/site-packages/airflow/cli/commands/task_command.py", line 184, in _run_raw_task
    error_file=args.error_file,
  File "/home/airflow/.local/lib/python3.7/site-packages/airflow/utils/session.py", line 70, in wrapper
    return func(*args, session=session, **kwargs)
  File "/home/airflow/.local/lib/python3.7/site-packages/airflow/models/taskinstance.py", line 1329, in _run_raw_task
    self._execute_task_with_callbacks(context)
  File "/home/airflow/.local/lib/python3.7/site-packages/airflow/models/taskinstance.py", line 1455, in _execute_task_with_callbacks
    result = self._execute_task(context, self.task)
  File "/home/airflow/.local/lib/python3.7/site-packages/airflow/models/taskinstance.py", line 1511, in _execute_task
    result = execute_callable(context=context)
  File "/home/airflow/.local/lib/python3.7/site-packages/airflow/operators/bash.py", line 188, in execute
    f'Bash command failed. The command returned a non-zero exit code {result.exit_code}.'
airflow.exceptions.AirflowException: Bash command failed. The command returned a non-zero exit code 22.
[2022-11-14 16:41:01,652] {local_task_job.py:154} INFO - Task exited with return code 1
[2022-11-14 16:41:01,722] {local_task_job.py:264} INFO - 0 downstream tasks scheduled from follow-on schedule check
