[2022-11-14 15:59:02,531] {taskinstance.py:1032} INFO - Dependencies all met for <TaskInstance: yellow_taxi_data_v2.download_dataset_task scheduled__2022-10-02T06:00:00+00:00 [queued]>
[2022-11-14 15:59:02,546] {taskinstance.py:1032} INFO - Dependencies all met for <TaskInstance: yellow_taxi_data_v2.download_dataset_task scheduled__2022-10-02T06:00:00+00:00 [queued]>
[2022-11-14 15:59:02,547] {taskinstance.py:1238} INFO - 
--------------------------------------------------------------------------------
[2022-11-14 15:59:02,547] {taskinstance.py:1239} INFO - Starting attempt 1 of 2
[2022-11-14 15:59:02,547] {taskinstance.py:1240} INFO - 
--------------------------------------------------------------------------------
[2022-11-14 15:59:02,562] {taskinstance.py:1259} INFO - Executing <Task(BashOperator): download_dataset_task> on 2022-10-02 06:00:00+00:00
[2022-11-14 15:59:02,570] {standard_task_runner.py:52} INFO - Started process 1651 to run task
[2022-11-14 15:59:02,579] {standard_task_runner.py:76} INFO - Running: ['***', 'tasks', 'run', 'yellow_taxi_data_v2', 'download_dataset_task', 'scheduled__2022-10-02T06:00:00+00:00', '--job-id', '301', '--raw', '--subdir', 'DAGS_FOLDER/data_ingestion_gcs.py', '--cfg-path', '/tmp/tmpvgnannxs', '--error-file', '/tmp/tmpctjdky95']
[2022-11-14 15:59:02,580] {standard_task_runner.py:77} INFO - Job 301: Subtask download_dataset_task
[2022-11-14 15:59:02,690] {logging_mixin.py:109} INFO - Running <TaskInstance: yellow_taxi_data_v2.download_dataset_task scheduled__2022-10-02T06:00:00+00:00 [running]> on host e030bae48f83
[2022-11-14 15:59:02,809] {warnings.py:110} WARNING - /home/***/.local/lib/python3.7/site-packages/***/utils/context.py:152: AirflowContextDeprecationWarning: Accessing 'execution_date' from the template is deprecated and will be removed in a future version. Please use 'data_interval_start' or 'logical_date' instead.
  warnings.warn(_create_deprecation_warning(key, self._deprecation_replacements[key]))

[2022-11-14 15:59:02,880] {taskinstance.py:1426} INFO - Exporting the following env vars:
AIRFLOW_CTX_DAG_OWNER=***
AIRFLOW_CTX_DAG_ID=yellow_taxi_data_v2
AIRFLOW_CTX_TASK_ID=download_dataset_task
AIRFLOW_CTX_EXECUTION_DATE=2022-10-02T06:00:00+00:00
AIRFLOW_CTX_DAG_RUN_ID=scheduled__2022-10-02T06:00:00+00:00
[2022-11-14 15:59:02,883] {subprocess.py:62} INFO - Tmp dir root location: 
 /tmp
[2022-11-14 15:59:02,884] {subprocess.py:74} INFO - Running command: ['bash', '-c', 'curl -sSLf https://d37ci6vzurychx.cloudfront.net/trip-data/yellow_tripdata_2022-10.parquet > /opt/***/yellow_tripdata_2022-10.parquet']
[2022-11-14 15:59:02,902] {subprocess.py:85} INFO - Output:
[2022-11-14 15:59:03,257] {subprocess.py:89} INFO - curl: (22) The requested URL returned error: 403
[2022-11-14 15:59:03,260] {subprocess.py:93} INFO - Command exited with return code 22
[2022-11-14 15:59:03,291] {taskinstance.py:1700} ERROR - Task failed with exception
Traceback (most recent call last):
  File "/home/airflow/.local/lib/python3.7/site-packages/airflow/models/taskinstance.py", line 1329, in _run_raw_task
    self._execute_task_with_callbacks(context)
  File "/home/airflow/.local/lib/python3.7/site-packages/airflow/models/taskinstance.py", line 1455, in _execute_task_with_callbacks
    result = self._execute_task(context, self.task)
  File "/home/airflow/.local/lib/python3.7/site-packages/airflow/models/taskinstance.py", line 1511, in _execute_task
    result = execute_callable(context=context)
  File "/home/airflow/.local/lib/python3.7/site-packages/airflow/operators/bash.py", line 188, in execute
    f'Bash command failed. The command returned a non-zero exit code {result.exit_code}.'
airflow.exceptions.AirflowException: Bash command failed. The command returned a non-zero exit code 22.
[2022-11-14 15:59:03,304] {taskinstance.py:1277} INFO - Marking task as UP_FOR_RETRY. dag_id=yellow_taxi_data_v2, task_id=download_dataset_task, execution_date=20221002T060000, start_date=20221114T155902, end_date=20221114T155903
[2022-11-14 15:59:03,332] {standard_task_runner.py:92} ERROR - Failed to execute job 301 for task download_dataset_task
Traceback (most recent call last):
  File "/home/airflow/.local/lib/python3.7/site-packages/airflow/task/task_runner/standard_task_runner.py", line 85, in _start_by_fork
    args.func(args, dag=self.dag)
  File "/home/airflow/.local/lib/python3.7/site-packages/airflow/cli/cli_parser.py", line 48, in command
    return func(*args, **kwargs)
  File "/home/airflow/.local/lib/python3.7/site-packages/airflow/utils/cli.py", line 92, in wrapper
    return f(*args, **kwargs)
  File "/home/airflow/.local/lib/python3.7/site-packages/airflow/cli/commands/task_command.py", line 298, in task_run
    _run_task_by_selected_method(args, dag, ti)
  File "/home/airflow/.local/lib/python3.7/site-packages/airflow/cli/commands/task_command.py", line 107, in _run_task_by_selected_method
    _run_raw_task(args, ti)
  File "/home/airflow/.local/lib/python3.7/site-packages/airflow/cli/commands/task_command.py", line 184, in _run_raw_task
    error_file=args.error_file,
  File "/home/airflow/.local/lib/python3.7/site-packages/airflow/utils/session.py", line 70, in wrapper
    return func(*args, session=session, **kwargs)
  File "/home/airflow/.local/lib/python3.7/site-packages/airflow/models/taskinstance.py", line 1329, in _run_raw_task
    self._execute_task_with_callbacks(context)
  File "/home/airflow/.local/lib/python3.7/site-packages/airflow/models/taskinstance.py", line 1455, in _execute_task_with_callbacks
    result = self._execute_task(context, self.task)
  File "/home/airflow/.local/lib/python3.7/site-packages/airflow/models/taskinstance.py", line 1511, in _execute_task
    result = execute_callable(context=context)
  File "/home/airflow/.local/lib/python3.7/site-packages/airflow/operators/bash.py", line 188, in execute
    f'Bash command failed. The command returned a non-zero exit code {result.exit_code}.'
airflow.exceptions.AirflowException: Bash command failed. The command returned a non-zero exit code 22.
[2022-11-14 15:59:03,358] {local_task_job.py:154} INFO - Task exited with return code 1
[2022-11-14 15:59:03,424] {local_task_job.py:264} INFO - 0 downstream tasks scheduled from follow-on schedule check
[2022-11-16 09:27:22,225] {taskinstance.py:1032} INFO - Dependencies all met for <TaskInstance: yellow_taxi_data_v2.download_dataset_task scheduled__2022-10-02T06:00:00+00:00 [queued]>
[2022-11-16 09:27:22,243] {taskinstance.py:1032} INFO - Dependencies all met for <TaskInstance: yellow_taxi_data_v2.download_dataset_task scheduled__2022-10-02T06:00:00+00:00 [queued]>
[2022-11-16 09:27:22,243] {taskinstance.py:1238} INFO - 
--------------------------------------------------------------------------------
[2022-11-16 09:27:22,243] {taskinstance.py:1239} INFO - Starting attempt 1 of 2
[2022-11-16 09:27:22,243] {taskinstance.py:1240} INFO - 
--------------------------------------------------------------------------------
[2022-11-16 09:27:22,262] {taskinstance.py:1259} INFO - Executing <Task(BashOperator): download_dataset_task> on 2022-10-02 06:00:00+00:00
[2022-11-16 09:27:22,272] {standard_task_runner.py:52} INFO - Started process 1016 to run task
[2022-11-16 09:27:22,281] {standard_task_runner.py:76} INFO - Running: ['***', 'tasks', 'run', 'yellow_taxi_data_v2', 'download_dataset_task', 'scheduled__2022-10-02T06:00:00+00:00', '--job-id', '839', '--raw', '--subdir', 'DAGS_FOLDER/data_ingestion_gcs.py', '--cfg-path', '/tmp/tmpfzpyhlhr', '--error-file', '/tmp/tmp_m4l74tr']
[2022-11-16 09:27:22,283] {standard_task_runner.py:77} INFO - Job 839: Subtask download_dataset_task
[2022-11-16 09:27:22,400] {logging_mixin.py:109} INFO - Running <TaskInstance: yellow_taxi_data_v2.download_dataset_task scheduled__2022-10-02T06:00:00+00:00 [running]> on host 75ceca4d9264
[2022-11-16 09:27:22,488] {warnings.py:110} WARNING - /home/***/.local/lib/python3.7/site-packages/***/utils/context.py:152: AirflowContextDeprecationWarning: Accessing 'execution_date' from the template is deprecated and will be removed in a future version. Please use 'data_interval_start' or 'logical_date' instead.
  warnings.warn(_create_deprecation_warning(key, self._deprecation_replacements[key]))

[2022-11-16 09:27:22,529] {taskinstance.py:1426} INFO - Exporting the following env vars:
AIRFLOW_CTX_DAG_OWNER=***
AIRFLOW_CTX_DAG_ID=yellow_taxi_data_v2
AIRFLOW_CTX_TASK_ID=download_dataset_task
AIRFLOW_CTX_EXECUTION_DATE=2022-10-02T06:00:00+00:00
AIRFLOW_CTX_DAG_RUN_ID=scheduled__2022-10-02T06:00:00+00:00
[2022-11-16 09:27:22,531] {subprocess.py:62} INFO - Tmp dir root location: 
 /tmp
[2022-11-16 09:27:22,533] {subprocess.py:74} INFO - Running command: ['bash', '-c', 'curl -sSLf https://d37ci6vzurychx.cloudfront.net/trip-data/yellow_tripdata_2022-10.parquet > /opt/***/yellow_tripdata_2022-10.parquet']
[2022-11-16 09:27:22,554] {subprocess.py:85} INFO - Output:
[2022-11-16 09:27:23,000] {subprocess.py:89} INFO - curl: (22) The requested URL returned error: 403
[2022-11-16 09:27:23,003] {subprocess.py:93} INFO - Command exited with return code 22
[2022-11-16 09:27:23,031] {taskinstance.py:1700} ERROR - Task failed with exception
Traceback (most recent call last):
  File "/home/airflow/.local/lib/python3.7/site-packages/airflow/models/taskinstance.py", line 1329, in _run_raw_task
    self._execute_task_with_callbacks(context)
  File "/home/airflow/.local/lib/python3.7/site-packages/airflow/models/taskinstance.py", line 1455, in _execute_task_with_callbacks
    result = self._execute_task(context, self.task)
  File "/home/airflow/.local/lib/python3.7/site-packages/airflow/models/taskinstance.py", line 1511, in _execute_task
    result = execute_callable(context=context)
  File "/home/airflow/.local/lib/python3.7/site-packages/airflow/operators/bash.py", line 188, in execute
    f'Bash command failed. The command returned a non-zero exit code {result.exit_code}.'
airflow.exceptions.AirflowException: Bash command failed. The command returned a non-zero exit code 22.
[2022-11-16 09:27:23,054] {taskinstance.py:1277} INFO - Marking task as UP_FOR_RETRY. dag_id=yellow_taxi_data_v2, task_id=download_dataset_task, execution_date=20221002T060000, start_date=20221116T092722, end_date=20221116T092723
[2022-11-16 09:27:23,078] {standard_task_runner.py:92} ERROR - Failed to execute job 839 for task download_dataset_task
Traceback (most recent call last):
  File "/home/airflow/.local/lib/python3.7/site-packages/airflow/task/task_runner/standard_task_runner.py", line 85, in _start_by_fork
    args.func(args, dag=self.dag)
  File "/home/airflow/.local/lib/python3.7/site-packages/airflow/cli/cli_parser.py", line 48, in command
    return func(*args, **kwargs)
  File "/home/airflow/.local/lib/python3.7/site-packages/airflow/utils/cli.py", line 92, in wrapper
    return f(*args, **kwargs)
  File "/home/airflow/.local/lib/python3.7/site-packages/airflow/cli/commands/task_command.py", line 298, in task_run
    _run_task_by_selected_method(args, dag, ti)
  File "/home/airflow/.local/lib/python3.7/site-packages/airflow/cli/commands/task_command.py", line 107, in _run_task_by_selected_method
    _run_raw_task(args, ti)
  File "/home/airflow/.local/lib/python3.7/site-packages/airflow/cli/commands/task_command.py", line 184, in _run_raw_task
    error_file=args.error_file,
  File "/home/airflow/.local/lib/python3.7/site-packages/airflow/utils/session.py", line 70, in wrapper
    return func(*args, session=session, **kwargs)
  File "/home/airflow/.local/lib/python3.7/site-packages/airflow/models/taskinstance.py", line 1329, in _run_raw_task
    self._execute_task_with_callbacks(context)
  File "/home/airflow/.local/lib/python3.7/site-packages/airflow/models/taskinstance.py", line 1455, in _execute_task_with_callbacks
    result = self._execute_task(context, self.task)
  File "/home/airflow/.local/lib/python3.7/site-packages/airflow/models/taskinstance.py", line 1511, in _execute_task
    result = execute_callable(context=context)
  File "/home/airflow/.local/lib/python3.7/site-packages/airflow/operators/bash.py", line 188, in execute
    f'Bash command failed. The command returned a non-zero exit code {result.exit_code}.'
airflow.exceptions.AirflowException: Bash command failed. The command returned a non-zero exit code 22.
[2022-11-16 09:27:23,134] {local_task_job.py:154} INFO - Task exited with return code 1
[2022-11-16 09:27:23,188] {local_task_job.py:264} INFO - 0 downstream tasks scheduled from follow-on schedule check
