[2022-11-14 16:46:32,965] {taskinstance.py:1032} INFO - Dependencies all met for <TaskInstance: fhv_taxi_data_v1.download_dataset_task scheduled__2022-10-02T08:00:00+00:00 [queued]>
[2022-11-14 16:46:32,981] {taskinstance.py:1032} INFO - Dependencies all met for <TaskInstance: fhv_taxi_data_v1.download_dataset_task scheduled__2022-10-02T08:00:00+00:00 [queued]>
[2022-11-14 16:46:32,981] {taskinstance.py:1238} INFO - 
--------------------------------------------------------------------------------
[2022-11-14 16:46:32,981] {taskinstance.py:1239} INFO - Starting attempt 2 of 2
[2022-11-14 16:46:32,981] {taskinstance.py:1240} INFO - 
--------------------------------------------------------------------------------
[2022-11-14 16:46:32,997] {taskinstance.py:1259} INFO - Executing <Task(BashOperator): download_dataset_task> on 2022-10-02 08:00:00+00:00
[2022-11-14 16:46:33,006] {standard_task_runner.py:52} INFO - Started process 5213 to run task
[2022-11-14 16:46:33,012] {standard_task_runner.py:76} INFO - Running: ['***', 'tasks', 'run', 'fhv_taxi_data_v1', 'download_dataset_task', 'scheduled__2022-10-02T08:00:00+00:00', '--job-id', '689', '--raw', '--subdir', 'DAGS_FOLDER/data_ingestion_gcs.py', '--cfg-path', '/tmp/tmpqivcff82', '--error-file', '/tmp/tmpn9xlrb47']
[2022-11-14 16:46:33,014] {standard_task_runner.py:77} INFO - Job 689: Subtask download_dataset_task
[2022-11-14 16:46:33,097] {logging_mixin.py:109} INFO - Running <TaskInstance: fhv_taxi_data_v1.download_dataset_task scheduled__2022-10-02T08:00:00+00:00 [running]> on host e030bae48f83
[2022-11-14 16:46:33,151] {warnings.py:110} WARNING - /home/***/.local/lib/python3.7/site-packages/***/utils/context.py:152: AirflowContextDeprecationWarning: Accessing 'execution_date' from the template is deprecated and will be removed in a future version. Please use 'data_interval_start' or 'logical_date' instead.
  warnings.warn(_create_deprecation_warning(key, self._deprecation_replacements[key]))

[2022-11-14 16:46:33,176] {taskinstance.py:1426} INFO - Exporting the following env vars:
AIRFLOW_CTX_DAG_OWNER=***
AIRFLOW_CTX_DAG_ID=fhv_taxi_data_v1
AIRFLOW_CTX_TASK_ID=download_dataset_task
AIRFLOW_CTX_EXECUTION_DATE=2022-10-02T08:00:00+00:00
AIRFLOW_CTX_DAG_RUN_ID=scheduled__2022-10-02T08:00:00+00:00
[2022-11-14 16:46:33,177] {subprocess.py:62} INFO - Tmp dir root location: 
 /tmp
[2022-11-14 16:46:33,178] {subprocess.py:74} INFO - Running command: ['bash', '-c', 'curl -sSLf https://d37ci6vzurychx.cloudfront.net/trip-data/fhv_tripdata_2022-10.parquet > /opt/***/fhv_tripdata_2022-10.parquet']
[2022-11-14 16:46:33,202] {subprocess.py:85} INFO - Output:
[2022-11-14 16:46:33,607] {subprocess.py:89} INFO - curl: (22) The requested URL returned error: 403
[2022-11-14 16:46:33,609] {subprocess.py:93} INFO - Command exited with return code 22
[2022-11-14 16:46:33,629] {taskinstance.py:1700} ERROR - Task failed with exception
Traceback (most recent call last):
  File "/home/airflow/.local/lib/python3.7/site-packages/airflow/models/taskinstance.py", line 1329, in _run_raw_task
    self._execute_task_with_callbacks(context)
  File "/home/airflow/.local/lib/python3.7/site-packages/airflow/models/taskinstance.py", line 1455, in _execute_task_with_callbacks
    result = self._execute_task(context, self.task)
  File "/home/airflow/.local/lib/python3.7/site-packages/airflow/models/taskinstance.py", line 1511, in _execute_task
    result = execute_callable(context=context)
  File "/home/airflow/.local/lib/python3.7/site-packages/airflow/operators/bash.py", line 188, in execute
    f'Bash command failed. The command returned a non-zero exit code {result.exit_code}.'
airflow.exceptions.AirflowException: Bash command failed. The command returned a non-zero exit code 22.
[2022-11-14 16:46:33,637] {taskinstance.py:1277} INFO - Marking task as FAILED. dag_id=fhv_taxi_data_v1, task_id=download_dataset_task, execution_date=20221002T080000, start_date=20221114T164632, end_date=20221114T164633
[2022-11-14 16:46:33,658] {standard_task_runner.py:92} ERROR - Failed to execute job 689 for task download_dataset_task
Traceback (most recent call last):
  File "/home/airflow/.local/lib/python3.7/site-packages/airflow/task/task_runner/standard_task_runner.py", line 85, in _start_by_fork
    args.func(args, dag=self.dag)
  File "/home/airflow/.local/lib/python3.7/site-packages/airflow/cli/cli_parser.py", line 48, in command
    return func(*args, **kwargs)
  File "/home/airflow/.local/lib/python3.7/site-packages/airflow/utils/cli.py", line 92, in wrapper
    return f(*args, **kwargs)
  File "/home/airflow/.local/lib/python3.7/site-packages/airflow/cli/commands/task_command.py", line 298, in task_run
    _run_task_by_selected_method(args, dag, ti)
  File "/home/airflow/.local/lib/python3.7/site-packages/airflow/cli/commands/task_command.py", line 107, in _run_task_by_selected_method
    _run_raw_task(args, ti)
  File "/home/airflow/.local/lib/python3.7/site-packages/airflow/cli/commands/task_command.py", line 184, in _run_raw_task
    error_file=args.error_file,
  File "/home/airflow/.local/lib/python3.7/site-packages/airflow/utils/session.py", line 70, in wrapper
    return func(*args, session=session, **kwargs)
  File "/home/airflow/.local/lib/python3.7/site-packages/airflow/models/taskinstance.py", line 1329, in _run_raw_task
    self._execute_task_with_callbacks(context)
  File "/home/airflow/.local/lib/python3.7/site-packages/airflow/models/taskinstance.py", line 1455, in _execute_task_with_callbacks
    result = self._execute_task(context, self.task)
  File "/home/airflow/.local/lib/python3.7/site-packages/airflow/models/taskinstance.py", line 1511, in _execute_task
    result = execute_callable(context=context)
  File "/home/airflow/.local/lib/python3.7/site-packages/airflow/operators/bash.py", line 188, in execute
    f'Bash command failed. The command returned a non-zero exit code {result.exit_code}.'
airflow.exceptions.AirflowException: Bash command failed. The command returned a non-zero exit code 22.
[2022-11-14 16:46:33,710] {local_task_job.py:154} INFO - Task exited with return code 1
[2022-11-14 16:46:33,776] {local_task_job.py:264} INFO - 0 downstream tasks scheduled from follow-on schedule check
